class BalanceException(Exception):
    pass

class BankAccount:
    def __init__(self, initailAmount, acctName):
        self.balance = initailAmount
        self.name = acctName
        print(f"\nAccount '{self.name}' created.\nBalance = ${self.balance:.2f}")

    def getBalance(self):
        print(f"\nAccount '{self.name}' Balance = ${self.balance:.2f}")

    def deposit(self, amount):
        self.balance = self.balance + amount
        print(f"\nDeposit Complete.")
        self.getBalance()

    def viableTransaction(self, amount):
        if self.balance >= amount:
            return
        else:
            raise BalanceException(
                f"\nSorry, account '{self.name}' only has a balance of ${self.balance:.2f}"
            )

    def withdraw(self, amount):
        try:
            self.viableTransaction(amount)
            self.balance = self.balance - amount
            print("\nWithdraw complete.")
            self.getBalance()
        except BalanceException as error:
            print(f"\nWithdraw interrupted: {error}")

    def transfer(self, amount, account):
        try:
            print('\n***********\n\n Beginning Transfer.. ðŸš€')
            self.viableTransaction(amount)
            self.withdraw(amount)
            account.deposit(amount)
            print('\nTransfer Completeâœ…')
        except BalanceException as error:
            print(f"\nTransfer interrupted: {error}")

        
class InterestRewardsAcct(BankAccount):
    def deposit(self, amount):
        self.balance = self.balance + (amount*1.05)
        print("\nDeposit Complete.")
        self.getBalance()


class SavingsAccount(InterestRewardsAcct):
    def __init__(self, initialAmount, acctName):
        super().__init__(initialAmount, acctName)
        self.fee = 5

    def withdraw(self, amount):
        try:
            self.viableTransaction(amount + self.fee)
            self.balance = self.balance - (amount+self.fee)
            print("\nWithdraw complete.")
            self.getBalance()
        except BalanceException as error:
            print(f"\nWithdraw interrupted: {error}")

        